{"uuid": "496b5649-0b17-4109-b2f6-e4e2665cae33", "children": ["7a8deccf-e9fd-4f3b-a3b6-6994a7efd2a7", "2346234d-169c-401a-8d2b-b861a276842f", "7d751601-660a-4ce4-9625-bb3678110310", "b8a8aa2c-f363-4ff9-958d-1bc33555532f", "9ec9b710-53de-4029-8cbb-6865d9e26287", "33ba7173-32d3-4800-9f0f-aebb564a874f"], "befores": [{"name": "init__driver", "status": "broken", "statusDetails": {"message": "selenium.common.exceptions.TimeoutException: Message: No connection could be made because the target machine actively refused it. (os error 10061)\n\n", "trace": "  File \"c:\\users\\admin\\appdata\\local\\programs\\python\\python38\\lib\\site-packages\\pluggy\\callers.py\", line 187, in _multicall\n    res = hook_impl.function(*args)\n  File \"c:\\users\\admin\\appdata\\local\\programs\\python\\python38\\lib\\site-packages\\_pytest\\fixtures.py\", line 1124, in pytest_fixture_setup\n    result = call_fixture_func(fixturefunc, request, kwargs)\n  File \"c:\\users\\admin\\appdata\\local\\programs\\python\\python38\\lib\\site-packages\\_pytest\\fixtures.py\", line 921, in call_fixture_func\n    fixture_result = next(generator)\n  File \"C:\\Users\\Admin\\PycharmProjects\\untitled1\\febdemo\\conftest.py\", line 17, in init__driver\n    web_driver = webdriver.Firefox(executable_path=\"C:\\\\Users\\\\Admin\\\\Downloads\\\\geckodriver-v0.27.0-win64\\\\geckodriver.exe\")\n  File \"c:\\users\\admin\\appdata\\local\\programs\\python\\python38\\lib\\site-packages\\selenium\\webdriver\\firefox\\webdriver.py\", line 170, in __init__\n    RemoteWebDriver.__init__(\n  File \"c:\\users\\admin\\appdata\\local\\programs\\python\\python38\\lib\\site-packages\\selenium\\webdriver\\remote\\webdriver.py\", line 157, in __init__\n    self.start_session(capabilities, browser_profile)\n  File \"c:\\users\\admin\\appdata\\local\\programs\\python\\python38\\lib\\site-packages\\selenium\\webdriver\\remote\\webdriver.py\", line 252, in start_session\n    response = self.execute(Command.NEW_SESSION, parameters)\n  File \"c:\\users\\admin\\appdata\\local\\programs\\python\\python38\\lib\\site-packages\\selenium\\webdriver\\remote\\webdriver.py\", line 321, in execute\n    self.error_handler.check_response(response)\n  File \"c:\\users\\admin\\appdata\\local\\programs\\python\\python38\\lib\\site-packages\\selenium\\webdriver\\remote\\errorhandler.py\", line 242, in check_response\n    raise exception_class(message, screen, stacktrace)\n"}, "start": 1614430398530, "stop": 1614430468967}], "start": 1614430398530, "stop": 1614430476078}